Workbook

Sheet Cover page
B3: Item | C3: Description(EN)
B4: Company name | C4: ILNEDA sp.z o.o.
B5: Company address | C5: Stanisława Dubois 36,
C6: 44-100 Gliwice
B7: KRS number | C7: 918940
B8: REGON number | C8: 389804151
B9: NIP number | C9: 631-269-93-90
B10: Contact person | C10: +48 575 835 862
B11: Member of the Board | C11: Juhyeong Jo
B12: Contact email | C12: ilneda@hutengroup.com
B13: Peported date | C13: 44565
B14: Client name | C14: LG Electronics sp.z o.o.
B15: Workers name | C15: Cyrille Njowo Nana
B16: Passport No | C16: 1037786
B17: date of Birth | C17: 18/03/1987
B18: Nationality | C18: Cameroonian
B19: Position | C19: Packer | D19: Pakowacz
B20: Ambacy name | C20: Yaounde
B21: Ambacy address | C21: Rue 1381,Nouvelle Route Bastos
B22: Work permit number | C22: A-13516/2022
B23: Work permit issue date | C23: 44567
B24: Salary | C24: 3,169zl
B25: Accommodation address | C25: ul Nowa 5a/2, 55-080 Pietrzykowice

Sheet Applications
B7: ='Cover page'!C4 -> ILNEDA sp.z o.o. | AG7: ='Cover page'!C13 -> 44565
B8: ='Cover page'!C5 -> Stanisława Dubois 36,
B9: ='Cover page'!C6 -> 44-100 Gliwice
B10: NIP | E10: ='Cover page'!C9 -> 631-269-93-90
B11: REGON | E11: ='Cover page'!C8 -> 389804151
B12: KRS | E12: ='Cover page'!C7 -> 918940
B13: Tel | E13: ='Cover page'!C10 -> +48 575 835 862
AN14: Wydział Konsularny
AN15: ='Cover page'!C20 -> Yaounde
AN16: ='Cover page'!C21 -> Rue 1381,Nouvelle Route Bastos
B19: INFORMACJA NA TEMAT APLIKACJI WIZOWYCH KANDYDATÓW DO PRACY
B21: Szanowni Państwo,
D23: Niniejszym pragnę poinformować, iż nasza firma jest zainteresowana zatrudnieniem obywateli | AD23: ='Cover page'!C18 -> Cameroonian
B24: na stanowisku | G24: ='Cover page'!D19 -> Pakowacz | O24: w pełnym wymiarze czasu pracy 160 godzin miesięcznie na umowę zlecenie.
B25: Potwierdzamy, że zgodnie z przesłanymi dokumentami gwarantujemy pracownikom pracę w naszej firmie na stanowisku
B26: =G24 -> Pakowacz | J26: pracownik ma zapewnione zakwaterowanie i dojazd zgodnie z umową
B27: przeslaną kandydatowi.
B28: Dnia | D28: ='Cover page'!C23 -> 44567 | K28: zostało wydane przez Wojewodę Śląskiego zezwolenie na pracę dla :
B29: ='Cover page'!C15 -> Cyrille Njowo Nana | L29: ,data urodzenia: | R29: ='Cover page'!C17 -> 18/03/1987 | X29: numer paszportu: | AD29: ='Cover page'!C16 -> 1037786
D30: Zwracam się z prośbą o wydanie pozytywnej decyzji wizowej dla wyżej wymienionej osoby, jeżeli
B31: niezbędne są dodatkowe informacje z naszej strony, bardzo proszę o kontakt.
B33: INFORMATION ON VISA CANDIDATES APPLICATIONS FOR EMPLOYMENT
B35: Dear Sir or Madam,
D37: I would like to inform you that our company is interested in hiring citizens of | Y37: ='Cover page'!C18 -> Cameroonian | AI37: for the position of
B38: ='Cover page'!C19 -> Packer | J38: , as a full-time 160 hours per month on a contract of mandate basis.
B39: We confirm that in accordance with the documents sent, we guarantee the employees to work in our company on the
B40: position of | F40: ='Cover page'!C19 -> Packer | N40: the employee is provided with accommodation and transport in accordance
B41: with the contract sent to the candidate.
B42: On the day of the | H42: ='Cover page'!C23 -> 44567 | O42: the West Pomeranian Voivode issued a work permit for :
B43: ='Cover page'!C15 -> Cyrille Njowo Nana | L43: ,date of birth; | Q43: ='Cover page'!C17 -> 18/03/1987 | W43: passport number; | AC43: ='Cover page'!C16 -> 1037786
D44: I kindly request your positive visa decision for the above mentioned person, if any additional information
B45: is required on our part, please feel free to contact me.
AN49: Z Wyrazami Szacunku
AN51: Sincerely

Sheet Letter of employment
B7: LETTER OF EMPTOYMENT
B9: This Letter of lntent to Contract of mandate is made and entered into, on the | Z9: ='Cover page'!C13 -> 44565 | AG9: by the between;
C11: ='Cover page'!C4 -> ILNEDA sp.z o.o.
C12: ='Cover page'!C5 -> Stanisława Dubois 36, | K12: ='Cover page'!C6 -> 44-100 Gliwice
C13: NIP | E13: ='Cover page'!C9 -> 631-269-93-90
C14: REGON | F14: ='Cover page'!C8 -> 389804151
C15: KRS | E15: ='Cover page'!C7 -> 918940
C16: (hereinafter referred to as Employer)
C18: and
C22: ='Cover page'!C15 -> Cyrille Njowo Nana
C23: (hereinafter referred to as Employee)
B25: The contract is valid under the condition that a type "D" visa is issued by the Embassy of the Republic of poland and upon
B26: arrivalto Poland.
B27: The Agreement complies with all employment rights in Poland and ensures respect for personal dignity,
B28: security and respect for the employee, in accordance with national as well as international labour law.
B30: - 1 -
B32: Basic Terms of Contract(main provision)
C34: Period of Employment | N34: 12 months, Renewable
C35: Working hours | N35: 40 hours per week
C36: Accommodation | N36: Free of charge, provided by The Employer by on the company rule
C37: Transportation | N37: Free of charge, provided by The Employer by on the company rule
C38: Medical | N38: Free medical treatment will be provided. (as per Polish Social lnsurance lnstitution)
C39: lnsurance | N39: As per Polish Social lnsurance lnstitution
C40: Salary | N40: ='Cover page'!C24 -> 3,169zl
C41: Overtime | N41: The Principal may ask the employee to work overtime according to the rules of the company (as per Poland and Schengen Law)
C42: Other terms and conditions | N42: As per Polish Civil Code/Labour Law
B44: - 2 -
C46: Renewal of Contract | N46: The contract is renewable with the mutual agreement of both the Employer and the Employee.
C47: Employee behaviour | N47: According to the employment contract,an Employee is required to behave in a certain way.
C48: -Punctuality -Honesty-Respect for others-Obedience to The law of poland. ln the event of non-compliance with these behaviours and failure to comply with any of the obligations set out in the job description below, the Employee will be subject to disciplinary action.
C51: Termination of contract | N51: The contract may be terminated by either party subject to one month's notice. The contract shall terminate at the end of its full term unless extended.
C52: Job description | N52: ='Cover page'!C19 -> Packer
C55: Job title | N55: Packer in product line
C56: Duties | N56: work on the production line, operation of production machines, preparing the final product, packing, labelling, maintaining cleanliness in the workplace
C57: Key requirements
C58: - Physically fit - Able to understand instructions either in English or Polish - Experience of working in small or commercial business or running own business as self-employed. - Good moral character - Efficient in completing tasks - Able to work in team and build good relationship - Must have basic numeracy skills
B60: - 3 -
B62: The Employer and Employee hereby declare that they understand and agree to sign and comply with these provisions They shall
B63: each retain a copy of the contract for future reference
C67: Signature of Employee | AE67: Employer Representative
...

Sheet Mandatory Quarantine
B7: ='Cover page'!C4 -> ILNEDA sp.z o.o. | AG7: ='Cover page'!C13 -> 44565
B8: ='Cover page'!C5 -> Stanisława Dubois 36,
B9: ='Cover page'!C6 -> 44-100 Gliwice
B10: NIP | E10: ='Cover page'!C9 -> 631-269-93-90
B11: REGON | E11: ='Cover page'!C8 -> 389804151
B12: KRS | E12: ='Cover page'!C7 -> 918940
B13: Tel | E13: ='Cover page'!C10 -> +48 575 835 862
AN14: Wydział Konsularny
AN15: ='Cover page'!C20 -> Yaounde
AN16: ='Cover page'!C21 -> Rue 1381,Nouvelle Route Bastos
C19: Dotyczy / Concerned :
C20: lmię i nazwisko / Name and surname | N20: ='Cover page'!C15 -> Cyrille Njowo Nana
C21: Narodowość / Nationality | L21: ='Cover page'!C18 -> Cameroonian
C22: Numer paszportu / passport no | M22: ='Cover page'!C16 -> 1037786
B24: INFORMACJA O OBOWIĄZKOWEJ KWARANTANNIE
B26: Szanowni Państwo,
D28: Chcielibyśmy zapewnić, że po przyjeździe ww. Pracownika do Polski, zastosujemy się do obowiązujących
B29: przepisów i zapewnimy tej osobie warunki do odbycia 14 dniowej kwarantanny domowej. Zaopiekujemy się tą osobą,
B30: dostarczymy jej niezbędne do życia środki, w tym wyżywienie, zgodnie z obowiązującymi przepisami.
B32: Adres przebywania tej osoby w okresie kwarantanny - | S32: ='Cover page'!C25 -> ul Nowa 5a/2, 55-080 Pietrzykowice
B33: lub inne mieszkanie dostępne w danym terminie.
B35: W przypadku pytań proszę o kontakt pod nr tel : | Q35: ='Cover page'!C10 -> +48 575 835 862
B37: INFORMATION ON MANDATORY QUARANTINE
B39: Dear Sir or Madam,
D41: We would like to assure that after arrival to Poland, the above-mentioned employee we will comply
B42: with applicable laws and we will provide for this person 14 days home quarantine. We will take care of this person,
B43: provide necessary living resources, including meals, in accordance with applicable regulations.
B45: The address ofthis person's stay during the quarantine period - | U45: ='Cover page'!C25 -> ul Nowa 5a/2, 55-080 Pietrzykowice
B46: or another flat available on a given date.
B48: lf you have any questions, please contact me at : | Q48: ='Cover page'!C10 -> +48 575 835 862
AN50: Z Wyrazami Szacunku
AN52: Sincerely

Sheet Confirmation of accommodation
B7: ='Cover page'!C4 -> ILNEDA sp.z o.o. | AG7: ='Cover page'!C13 -> 44565
B8: ='Cover page'!C5 -> Stanisława Dubois 36,
B9: ='Cover page'!C6 -> 44-100 Gliwice
B10: NIP | E10: ='Cover page'!C9 -> 631-269-93-90
B11: REGON | E11: ='Cover page'!C8 -> 389804151
B12: KRS | E12: ='Cover page'!C7 -> 918940
B13: Tel | E13: ='Cover page'!C10 -> +48 575 835 862
AN14: Wydział Konsularny
AN15: ='Cover page'!C20 -> Yaounde
AN16: ='Cover page'!C21 -> Rue 1381,Nouvelle Route Bastos
C19: Dotyczy / Concerned :
C20: lmię i nazwisko / Name and surname | N20: ='Cover page'!C15 -> Cyrille Njowo Nana
C21: Narodowość / Nationality | L21: ='Cover page'!C18 -> Cameroonian
C22: Numer paszportu / passport no | M22: ='Cover page'!C16 -> 1037786
B24: Potwierdzenie zakwaterowania Confirmation of accommodation
B26: Szanowni Państwo,
D28: Jako firma odpowiadająca za rekrutacje pracowników z | W28: ='Cover page'!C18 -> Cameroonian
D29: gwarantujemy Pani/Panu | M29: ='Cover page'!C15 -> Cyrille Njowo Nana
D30: Legitymującej/mu się paszportem o numerze : | T30: ='Cover page'!C16 -> 1037786
D31: zakwaterowanie w mieszkaniach firmowych w Polsce pod adresem :
D32: ='Cover page'!C25 -> ul Nowa 5a/2, 55-080 Pietrzykowice
B34: Dear Sir or Madam,
D35: As a Company responsible for the recruitment of employees from | Y35: ='Cover page'!C18 -> Cameroonian
D36: we guarantee Mr/Mrs | K36: ='Cover page'!C15 -> Cyrille Njowo Nana
D37: Passport number : | J37: ='Cover page'!C16 -> 1037786
D38: accommodation in corporate apartments : | P38: ='Cover page'!C25 -> ul Nowa 5a/2, 55-080 Pietrzykowice
AN46: Z Wyrazami Szacunku
AN48: Sincerely
